function* genFunc() {

    yield 'a';
    yield 'b';
    throw new Error("error thrown by genFunc()!");

    // from here unreachable code
    yield 'c';
    yield 'd';

}

var genObject = genFunc();

try{
    var a = genObject.next(); // Object {value: 'a', done: false}
    var b = genObject.next(); // Object {value: 'b', done: false}
    var c = genObject.next(); // undefined <-- since an uncaught error was thrown, the generator function terminated
    //console.log("error thrown by genFunc()!") occurs
    var d = genObject.next(); // undefined <-- other yield statements are ignored after the error
}
catch(e){
    console.log(e.message);
}